Workbook

Sheet Base_de_Datos
A1: SISTEMA DE REGISTRO Y CONTROL DE ATLETAS - BASE DE DATOS GENERAL
A3: Listado general de atletas registrados, datos físicos, condiciones médicas y contactos de emergencia.
A4: ID Atleta | B4: Fecha Ingreso | C4: Nombres | D4: Apellidos | E4: Cédula / Doc | F4: Fecha Nac. | G4: Edad | H4: Peso (kg) | I4: Estatura (m) | J4: IMC | K4: Situación de Salud / Alergias | L4: Nombre Representante | M4: Parentesco | N4: Teléfono Rep. | O4: Teléfono Emergencia | P4: Ruta / Nombre Foto | Q4: Estatus
A5: ATL-001 | B5: 2025-01-15 | C5: Carlos Eduardo | D5: Mendoza Pérez | E5: V-30.123.456 | F5: 2008-05-12 | G5: =IF(F5<>"",INT((TODAY()-F5)/365.25),"") -> 18 | H5: 68.5 | I5: 1.75 | J5: =IF(AND(H5>0,I5>0),ROUND(H5/(I5^2),1),"") -> 22.4 | K5: Sin novedades médicas | L5: Roberto Mendoza | M5: Padre | N5: 0414-1234567 | O5: 0424-7654321 | P5: carlos_mendoza.jpg | Q5: Activo
A6: ATL-002 | B6: 2025-01-20 | C6: Sofía Valentina | D6: Gómez Rivas | E6: V-31.456.789 | F6: 2009-08-24 | G6: =IF(F6<>"",INT((TODAY()-F6)/365.25),"") -> 17 | H6: 54 | I6: 1.62 | J6: =IF(AND(H6>0,I6>0),ROUND(H6/(I6^2),1),"") -> 20.6 | K6: Alergia a la Penicilina | L6: Elena Rivas | M6: Madre | N6: 0412-9876543 | O6: 0416-5554433 | P6: sofia_gomez.jpg | Q6: Activo
A7: ATL-003 | B7: 2025-02-01 | C7: Erick José | D7: Lambert Silva | E7: V-29.876.543 | F7: 2007-11-03 | G7: =IF(F7<>"",INT((TODAY()-F7)/365.25),"") -> 18 | H7: 72 | I7: 1.82 | J7: =IF(AND(H7>0,I7>0),ROUND(H7/(I7^2),1),"") -> 21.7 | K7: Ninguna | L7: José Lambert | M7: Padre | N7: 0424-1112233 | O7: 0414-9998877 | P7: erick_lambert.jpg | Q7: Activo
A8: ATL-004 | B8: 2025-02-10 | C8: Mariana Isabel | D8: Torres Castro | E8: V-32.111.222 | F8: 2010-03-15 | G8: =IF(F8<>"",INT((TODAY()-F8)/365.25),"") -> 16 | H8: 48 | I8: 1.58 | J8: =IF(AND(H8>0,I8>0),ROUND(H8/(I8^2),1),"") -> 19.2 | K8: Asma leve (Usa Inhalador) | L8: Carmen Castro | M8: Madre | N8: 0416-3334455 | O8: 0412-7778899 | P8: mariana_torres.jpg | Q8: Activo
A9: ATL-005 | B9: 2025-03-05 | C9: Gabriel Alejandro | D9: Rojas Medina | E9: V-30.555.666 | F9: 2008-09-30 | G9: =IF(F9<>"",INT((TODAY()-F9)/365.25),"") -> 17 | H9: 70 | I9: 1.78 | J9: =IF(AND(H9>0,I9>0),ROUND(H9/(I9^2),1),"") -> 22.1 | K9: Intolerante a la Lactosa | L9: Fernando Rojas | M9: Padre | N9: 0414-6667788 | O9: 0424-2223344 | P9: gabriel_rojas.jpg | Q9: Activo
A10: ATL-006 | B10: 2025-03-12 | C10: Daniela Victoria | D10: López Hernández | E10: V-31.888.999 | F10: 2009-12-18 | G10: =IF(F10<>"",INT((TODAY()-F10)/365.25),"") -> 16 | H10: 56.5 | I10: 1.65 | J10: =IF(AND(H10>0,I10>0),ROUND(H10/(I10^2),1),"") -> 20.8 | K10: Sin novedades médicas | L10: Patricia Hernández | M10: Madre | N10: 0424-8889900 | O10: 0414-4445566 | P10: daniela_lopez.jpg | Q10: Activo
A11: ATL-007 | B11: 2025-04-01 | C11: Luis Fernando | D11: Díaz Morales | E11: V-29.333.444 | F11: 2007-04-25 | G11: =IF(F11<>"",INT((TODAY()-F11)/365.25),"") -> 19 | H11: 75 | I11: 1.85 | J11: =IF(AND(H11>0,I11>0),ROUND(H11/(I11^2),1),"") -> 21.9 | K11: Lesión previa en rodilla izquierda (recuperado) | L11: Luis Díaz Sr. | M11: Padre | N11: 0412-1110000 | O11: 0416-2221111 | P11: luis_diaz.jpg | Q11: Activo
A12: ATL-008 | B12: 2025-04-18 | C12: Camila Andrea | D12: Sánchez Romero | E12: V-32.444.555 | F12: 2010-07-08 | G12: =IF(F12<>"",INT((TODAY()-F12)/365.25),"") -> 16 | H12: 50 | I12: 1.6 | J12: =IF(AND(H12>0,I12>0),ROUND(H12/(I12^2),1),"") -> 19.5 | K12: Sin novedades médicas | L12: Andrea Romero | M12: Madre | N12: 0414-5556677 | O12: 0424-8887766 | P12: camila_sanchez.jpg | Q12: Activo

Sheet Ficha_Individual
B1: FICHA TÉCNICA E INDIVIDUAL DEL ATLETA
B4: SELECCIONAR ATLETA (ID): | C4: ATL-001 | D4: ◄ Seleccione un ID de la lista para cargar los datos del atleta automáticamente
B6: 📷 FOTO TIPO CARNET (Inserta o carga foto aquí) | D6: ID del Atleta: | E6: =IFERROR(VLOOKUP(C4,Base_de_Datos!A5:Q100,1,FALSE)," ") -> ATL-001 | F6: Estatus: | G6: =IFERROR(VLOOKUP(C4,Base_de_Datos!A5:Q100,17,FALSE)," ") -> Activo
D7: Nombres: | E7: =IFERROR(VLOOKUP(C4,Base_de_Datos!A5:Q100,3,FALSE)," ") -> Carlos Eduardo | F7: Apellidos: | G7: =IFERROR(VLOOKUP(C4,Base_de_Datos!A5:Q100,4,FALSE)," ") -> Mendoza Pérez
D8: Cédula / Doc: | E8: =IFERROR(VLOOKUP(C4,Base_de_Datos!A5:Q100,5,FALSE)," ") -> V-30.123.456 | F8: Fecha de Ingreso: | G8: =IFERROR(VLOOKUP(C4,Base_de_Datos!A5:Q100,2,FALSE)," ") -> 2025-01-15
D9: Fecha Nacimiento: | E9: =IFERROR(VLOOKUP(C4,Base_de_Datos!A5:Q100,6,FALSE)," ") -> 2008-05-12 | F9: Edad: | G9: =IFERROR(VLOOKUP(C4,Base_de_Datos!A5:Q100,7,FALSE)&" años"," ") -> 18 años
B14: PERFIL FÍSICO Y CONDICIÓN DE SALUD
B15: Peso (kg): | C15: =IFERROR(VLOOKUP(C4,Base_de_Datos!A5:Q100,8,FALSE)," ") -> 68.5 | D15: Estatura (m): | E15: =IFERROR(VLOOKUP(C4,Base_de_Datos!A5:Q100,9,FALSE)," ") -> 1.75 | F15: IMC (Índice Masa Corp.): | G15: =IFERROR(VLOOKUP(C4,Base_de_Datos!A5:Q100,10,FALSE)," ") -> 22.4
B16: Situación / Condición Médica y Alergias: | D16: =IFERROR(VLOOKUP(C4,Base_de_Datos!A5:Q100,11,FALSE)," ") -> Sin novedades médicas
B19: DATOS DEL REPRESENTANTE Y CONTACTOS DE EMERGENCIA
B20: Nombre Representante: | C20: =IFERROR(VLOOKUP(C4,Base_de_Datos!A5:Q100,12,FALSE)," ") -> Roberto Mendoza | E20: Parentesco: | F20: =IFERROR(VLOOKUP(C4,Base_de_Datos!A5:Q100,13,FALSE)," ") -> Padre
B21: Teléfono Representante: | C21: =IFERROR(VLOOKUP(C4,Base_de_Datos!A5:Q100,14,FALSE)," ") -> 0414-1234567 | E21: Teléfono Emergencia: | F21: =IFERROR(VLOOKUP(C4,Base_de_Datos!A5:Q100,15,FALSE)," ") -> 0424-7654321
B23: REGISTRO DE FOTO Y ARCHIVOS ADJUNTOS
B24: Nombre Archivo Foto: | C24: =IFERROR(VLOOKUP(C4,Base_de_Datos!A5:Q100,16,FALSE)," ") -> carlos_mendoza.jpg | E24: Ubicación en Sistema: | F24: ="fotos/" & C24 -> fotos/carlos_mendoza.jpg
B26: 💡 ACCIONES CON MACRO VBA: Para cargar la foto de forma automática o imprimir esta ficha en PDF, ejecute la Macro desde el menú o use el botón asignado en Excel.

Sheet Fichas_Todos_Impresion
A1: CATÁLOGO Y FICHAS DE IMPRESIÓN DE TODOS LOS ATLETAS
A3: Formato preparado para impresión masiva. Cada tarjeta contiene la foto, datos personales, condición física, médica y contactos de emergencia.
A5: =IF(Base_de_Datos!A5<>"", "FICHA TÉCNICA - " & Base_de_Datos!A5 & ": " & Base_de_Datos!C5 & " " & Base_de_Datos!D5, "") -> FICHA TÉCNICA - ATL-001: Carlos Eduardo Mendoza Pérez
A6: 📷 FOTO CARNET | B6: Cédula: | C6: =Base_de_Datos!E5 -> V-30.123.456 | D6: Fecha Nac.: | E6: =Base_de_Datos!F5 -> 2008-05-12 | F6: Edad: | G6: =Base_de_Datos!G5 & " años" -> 18 años
B7: Ingreso: | C7: =Base_de_Datos!B5 -> 2025-01-15 | D7: Peso / Est.: | E7: =Base_de_Datos!H5 & " kg / " & Base_de_Datos!I5 & " m" -> 68,5 kg / 1,75 m | F7: IMC: | G7: =Base_de_Datos!J5 -> 22.4
B8: Salud / Med.: | C8: =Base_de_Datos!K5 -> Sin novedades médicas
B10: Representante: | C10: =Base_de_Datos!L5 -> Roberto Mendoza | E10: Parentesco: | F10: =Base_de_Datos!M5 -> Padre
B11: Tel. Rep.: | C11: =Base_de_Datos!N5 -> 0414-1234567 | E11: Emergencia: | F11: =Base_de_Datos!O5 -> 0424-7654321
A12: ✂ ------------------------------------------------------------------------------------------------------------------------
A14: =IF(Base_de_Datos!A6<>"", "FICHA TÉCNICA - " & Base_de_Datos!A6 & ": " & Base_de_Datos!C6 & " " & Base_de_Datos!D6, "") -> FICHA TÉCNICA - ATL-002: Sofía Valentina Gómez Rivas
A15: 📷 FOTO CARNET | B15: Cédula: | C15: =Base_de_Datos!E6 -> V-31.456.789 | D15: Fecha Nac.: | E15: =Base_de_Datos!F6 -> 2009-08-24 | F15: Edad: | G15: =Base_de_Datos!G6 & " años" -> 17 años
B16: Ingreso: | C16: =Base_de_Datos!B6 -> 2025-01-20 | D16: Peso / Est.: | E16: =Base_de_Datos!H6 & " kg / " & Base_de_Datos!I6 & " m" -> 54 kg / 1,62 m | F16: IMC: | G16: =Base_de_Datos!J6 -> 20.6
B17: Salud / Med.: | C17: =Base_de_Datos!K6 -> Alergia a la Penicilina
B19: Representante: | C19: =Base_de_Datos!L6 -> Elena Rivas | E19: Parentesco: | F19: =Base_de_Datos!M6 -> Madre
B20: Tel. Rep.: | C20: =Base_de_Datos!N6 -> 0412-9876543 | E20: Emergencia: | F20: =Base_de_Datos!O6 -> 0416-5554433
A21: ✂ ------------------------------------------------------------------------------------------------------------------------
A23: =IF(Base_de_Datos!A7<>"", "FICHA TÉCNICA - " & Base_de_Datos!A7 & ": " & Base_de_Datos!C7 & " " & Base_de_Datos!D7, "") -> FICHA TÉCNICA - ATL-003: Erick José Lambert Silva
A24: 📷 FOTO CARNET | B24: Cédula: | C24: =Base_de_Datos!E7 -> V-29.876.543 | D24: Fecha Nac.: | E24: =Base_de_Datos!F7 -> 2007-11-03 | F24: Edad: | G24: =Base_de_Datos!G7 & " años" -> 18 años
B25: Ingreso: | C25: =Base_de_Datos!B7 -> 2025-02-01 | D25: Peso / Est.: | E25: =Base_de_Datos!H7 & " kg / " & Base_de_Datos!I7 & " m" -> 72 kg / 1,82 m | F25: IMC: | G25: =Base_de_Datos!J7 -> 21.7
B26: Salud / Med.: | C26: =Base_de_Datos!K7 -> Ninguna
B28: Representante: | C28: =Base_de_Datos!L7 -> José Lambert | E28: Parentesco: | F28: =Base_de_Datos!M7 -> Padre
B29: Tel. Rep.: | C29: =Base_de_Datos!N7 -> 0424-1112233 | E29: Emergencia: | F29: =Base_de_Datos!O7 -> 0414-9998877
A30: ✂ ------------------------------------------------------------------------------------------------------------------------
A32: =IF(Base_de_Datos!A8<>"", "FICHA TÉCNICA - " & Base_de_Datos!A8 & ": " & Base_de_Datos!C8 & " " & Base_de_Datos!D8, "") -> FICHA TÉCNICA - ATL-004: Mariana Isabel Torres Castro
A33: 📷 FOTO CARNET | B33: Cédula: | C33: =Base_de_Datos!E8 -> V-32.111.222 | D33: Fecha Nac.: | E33: =Base_de_Datos!F8 -> 2010-03-15 | F33: Edad: | G33: =Base_de_Datos!G8 & " años" -> 16 años
B34: Ingreso: | C34: =Base_de_Datos!B8 -> 2025-02-10 | D34: Peso / Est.: | E34: =Base_de_Datos!H8 & " kg / " & Base_de_Datos!I8 & " m" -> 48 kg / 1,58 m | F34: IMC: | G34: =Base_de_Datos!J8 -> 19.2
B35: Salud / Med.: | C35: =Base_de_Datos!K8 -> Asma leve (Usa Inhalador)
B37: Representante: | C37: =Base_de_Datos!L8 -> Carmen Castro | E37: Parentesco: | F37: =Base_de_Datos!M8 -> Madre
B38: Tel. Rep.: | C38: =Base_de_Datos!N8 -> 0416-3334455 | E38: Emergencia: | F38: =Base_de_Datos!O8 -> 0412-7778899
A39: ✂ ------------------------------------------------------------------------------------------------------------------------
A41: =IF(Base_de_Datos!A9<>"", "FICHA TÉCNICA - " & Base_de_Datos!A9 & ": " & Base_de_Datos!C9 & " " & Base_de_Datos!D9, "") -> FICHA TÉCNICA - ATL-005: Gabriel Alejandro Rojas Medina
A42: 📷 FOTO CARNET | B42: Cédula: | C42: =Base_de_Datos!E9 -> V-30.555.666 | D42: Fecha Nac.: | E42: =Base_de_Datos!F9 -> 2008-09-30 | F42: Edad: | G42: =Base_de_Datos!G9 & " años" -> 17 años
B43: Ingreso: | C43: =Base_de_Datos!B9 -> 2025-03-05 | D43: Peso / Est.: | E43: =Base_de_Datos!H9 & " kg / " & Base_de_Datos!I9 & " m" -> 70 kg / 1,78 m | F43: IMC: | G43: =Base_de_Datos!J9 -> 22.1
B44: Salud / Med.: | C44: =Base_de_Datos!K9 -> Intolerante a la Lactosa
B46: Representante: | C46: =Base_de_Datos!L9 -> Fernando Rojas | E46: Parentesco: | F46: =Base_de_Datos!M9 -> Padre
B47: Tel. Rep.: | C47: =Base_de_Datos!N9 -> 0414-6667788 | E47: Emergencia: | F47: =Base_de_Datos!O9 -> 0424-2223344
A48: ✂ ------------------------------------------------------------------------------------------------------------------------
A50: =IF(Base_de_Datos!A10<>"", "FICHA TÉCNICA - " & Base_de_Datos!A10 & ": " & Base_de_Datos!C10 & " " & Base_de_Datos!D10, "") -> FICHA TÉCNICA - ATL-006: Daniela Victoria López Hernández
A51: 📷 FOTO CARNET | B51: Cédula: | C51: =Base_de_Datos!E10 -> V-31.888.999 | D51: Fecha Nac.: | E51: =Base_de_Datos!F10 -> 2009-12-18 | F51: Edad: | G51: =Base_de_Datos!G10 & " años" -> 16 años
B52: Ingreso: | C52: =Base_de_Datos!B10 -> 2025-03-12 | D52: Peso / Est.: | E52: =Base_de_Datos!H10 & " kg / " & Base_de_Datos!I10 & " m" -> 56,5 kg / 1,65 m | F52: IMC: | G52: =Base_de_Datos!J10 -> 20.8
...

Sheet Codigo_VBA_y_Manual
A1: GUÍA DE USO Y CÓDIGO MACRO VBA REGISTRO DE ATLETAS
A4: PASO 1: HABILITAR MACROS EN EXCEL
A5: 1. Guarde este archivo con la extensión '.xlsm' (Libro de Excel habilitado para macros).
A6: 2. Al abrir el archivo por primera vez, haga clic en 'Habilitar contenido' o 'Habilitar edición' en la barra superior amarilla.
A8: PASO 2: INSTALAR EL CÓDIGO MACRO
A9: 1. Presione las teclas 'ALT + F11' en su teclado para abrir el Editor de Visual Basic (VBA).
A10: 2. En el menú superior de VBA, haga clic en 'Insertar' -> 'Módulo'.
A11: 3. Copie todo el código VBA que se muestra abajo y péguelo en la ventana del Módulo.
A12: 4. Cierre la ventana de Visual Basic (ALT + Q) y guarde el archivo.
A14: PASO 3: ORGANIZACIÓN DE LAS FOTOS DE LOS ATLETAS
A15: 1. Cree una carpeta llamada 'fotos' en la misma ubicación donde guardó este archivo de Excel.
A16: 2. Coloque allí las imágenes tipo carnet de cada atleta en formato JPG o PNG.
... A20: ' ============================================================================== ' CÓDIGO MACRO VBA: CONTROL DE ATLETAS, CARGA DE FOTOS Y GENERACIÓN DE PDFs ' ============================================================================== Sub CargarFotoAtleta() ' Carga la foto del atleta seleccionado en la Ficha Individual Dim wsInd As Worksheet Dim wsDB As Worksheet Dim nombreFoto As String Dim rutaCarpeta As String Dim rutaCompleta As String Dim shp As Shape Dim rangoFoto As Range Set wsInd = ThisWorkbook.Sheets("Ficha_Individual") Set wsDB = ThisWorkbook.Sheets("Base_de_Datos") ' Obtener nombre de la foto cargada en Ficha Individual (Celda C24) nombreFoto = wsInd.Range("C24").Value ' Definir rango de la celda donde va la foto (B6:C12) Set rangoFoto = wsInd.Range("B6:C12") ' Eliminar fotos previas en el rango For Each shp In wsInd.Shapes If Not shp.TopLeftCell Is Nothing Then If Not Intersect(shp.TopLeftCell, rangoFoto) Is Nothing Then shp.Delete End If End If Next shp If Trim(nombreFoto) = "" Or nombreFoto = " " Then MsgBox "No hay una foto asignada para este atleta.", vbInformation, "Atención" Exit Sub End If ' Ruta de la carpeta de fotos (Carpeta 'fotos' en la misma ruta del libro) rutaCarpeta = ThisWorkbook.Path & "\fotos\" rutaCompleta = rutaCarpeta & nombreFoto ' Verificar si existe el archivo de imagen If Dir(rutaCompleta) <> "" Then Dim img As Picture Set img = wsInd.Pictures.Insert(rutaCompleta) With img .Left = rangoFoto.Left + 2 .Top = rangoFoto.Top + 2 .Width = rangoFoto.Width - 4 .Height = rangoFoto.Height - 4 .Placement = xlMoveAndSize End With Else MsgBox "No se encontró el archivo de foto en: " & rutaCompleta & vbCrLf & _ "Asegúrese de guardar la imagen en la carpeta 'fotos'.", vbWarning, "Foto No Encontrada" End If End Sub Sub ExportarFichaPDF() ' Exporta la Ficha Individual actual a un archivo PDF Dim wsInd As Worksheet Dim idAtleta As String Dim rutaPDF As String Set wsInd = ThisWorkbook.Sheets("Ficha_Individual") idAtleta = wsInd.Range("C4").Value If idAtleta = "" Then MsgBox "Por favor seleccione un ID de atleta válido.", vbExclamation, "Error" Exit Sub End If ' Generar o actualizar foto antes de exportar Call CargarFotoAtleta rutaPDF = ThisWorkbook.Path & "\Ficha_Atleta_" & idAtleta & ".pdf" wsInd.ExportAsFixedFormat Type:=xlTypePDF, Filename:=rutaPDF, _ Quality:=xlQualityStandard, IncludeDocProperties:=True, _ IgnorePrintAreas:=False, OpenAfterPublish:=True MsgBox "La ficha técnica ha sido exportada con éxito en:" & vbCrLf & rutaPDF, vbInformation, "Éxito" End Sub Sub ImprimirFichasTodos() ' Imprime o exporta a PDF la lista completa de fichas de la hoja Fichas_Todos_Impresion Dim wsAll As Worksheet Dim rutaPDF As String Set wsAll = ThisWorkbook.Sheets("Fichas_Todos_Impresion") rutaPDF = ThisWorkbook.Path & "\Catálogo_Fichas_Todos_Atletas.pdf" wsAll.ExportAsFixedFormat Type:=xlTypePDF, Filename:=rutaPDF, _ Quality:=xlQualityStandard, IncludeDocProperties:=True, _ IgnorePrintAreas:=False, OpenAfterPublish:=True MsgBox "El catálogo completo de fichas se exportó a PDF:" & vbCrLf & rutaPDF, vbInformation, "Exportación Completada" End Sub
